<?xml version="1.0" encoding="utf-8"?>
<!-- This URDF was automatically created by SolidWorks to URDF Exporter! Originally created by Stephen Brawner (brawner@gmail.com) 
     Commit Version: 1.5.1-0-g916b5db  Build Version: 1.5.7152.31018
     For more information, please see http://wiki.ros.org/sw_urdf_exporter -->
<robot
  name="lower_limb">
  <link
    name="Back_Base_Link">
    <inertial>
      <origin
        xyz="0.102999774541297 1.05565171604205E-08 -0.01817224156931"
        rpy="0 0 0" />
      <mass
        value="0.000000000001" />
      <inertia
        ixx="0.287991764742564"
        ixy="4.03119244398634E-09"
        ixz="0.00975876307734881"
        iyy="0.218183102338654"
        iyz="-5.72291606644722E-09"
        izz="0.12372998211452" />
    </inertial>
    <visual>
      <origin
        xyz="0 0 0"
        rpy="0 0 0" />
      <geometry>
        <mesh
          filename="package://exoskeleton_description/meshes/Back_Base_Link.STL" />
      </geometry>
      <material
        name="">
        <color
          rgba="0.898039215686275 0.917647058823529 0.929411764705882 1" />
      </material>
    </visual>
    <collision>
      <origin
        xyz="0 0 0"
        rpy="0 0 0" />
      <geometry>
        <mesh
          filename="package://exoskeleton_description/meshes/Back_Base_Link.STL" />
      </geometry>
    </collision>
  </link>
  <link
    name="Left_Hip_Link">
    <inertial>
      <origin
        xyz="-1.3735040874728E-05 0.0179559979496652 -0.0878442552563184"
        rpy="0 0 0" />
      <mass
        value="0.62727954916709" />
      <inertia
        ixx="0.000803551783618585"
        ixy="-5.17981149005877E-08"
        ixz="2.29207102245784E-07"
        iyy="0.00122780019469989"
        iyz="-2.98500736137851E-05"
        izz="0.000525693313567132" />
    </inertial>
    <visual>
      <origin
        xyz="0 0 0"
        rpy="0 0 0" />
      <geometry>
        <mesh
          filename="package://exoskeleton_description/meshes/Left_Hip_Link.STL" />
      </geometry>
      <material
        name="">
        <color
          rgba="0.792156862745098 0.819607843137255 0.933333333333333 1" />
      </material>
    </visual>
    <collision>
      <origin
        xyz="0 0 0"
        rpy="0 0 0" />
      <geometry>
        <mesh
          filename="package://exoskeleton_description/meshes/Left_Hip_Link.STL" />
      </geometry>
    </collision>
  </link>
  <joint
    name="Left_Hip_Joint"
    type="revolute">
    <origin
      xyz="0.2243 0.208 -0.283"
      rpy="0 0 0" />
    <parent
      link="Back_Base_Link" />
    <child
      link="Left_Hip_Link" />
    <axis
      xyz="0 0 -1" />
    <limit
      lower="-3.0543261"
      upper="3.0543261"
      effort="100"
      velocity="100" />
  </joint>
  <link
    name="Left_Thigh_Link">
    <inertial>
      <origin
        xyz="0.140127137492953 0.164862799184004 -0.00686232636978185"
        rpy="0 0 0" />
      <mass
        value="1.99015186746122" />
      <inertia
        ixx="0.00826856226696965"
        ixy="-0.00414176527978269"
        ixz="-0.000304599567683225"
        iyy="0.00690797410500549"
        iyz="-0.0003572757112064"
        izz="0.0133862450193977" />
    </inertial>
    <visual>
      <origin
        xyz="0 0 0"
        rpy="0 0 0" />
      <geometry>
        <mesh
          filename="package://exoskeleton_description/meshes/Left_Thigh_Link.STL" />
      </geometry>
      <material
        name="">
        <color
          rgba="0.898039215686275 0.917647058823529 0.929411764705882 1" />
      </material>
    </visual>
    <collision>
      <origin
        xyz="0 0 0"
        rpy="0 0 0" />
      <geometry>
        <mesh
          filename="package://exoskeleton_description/meshes/Left_Thigh_Link.STL" />
      </geometry>
    </collision>
  </link>
  <joint
    name="Left_Thigh_Joint"
    type="revolute">
    <origin
      xyz="0 -0.012 -0.097"
      rpy="-1.5708 0 0" />
    <parent
      link="Left_Hip_Link" />
    <child
      link="Left_Thigh_Link" />
    <axis
      xyz="0 0 1" />
    <limit
      lower="-3.0543261"
      upper="3.0543261"
      effort="100"
      velocity="100" />
  </joint>
  <link
    name="Left_Calf_Link">
    <inertial>
      <origin
        xyz="-0.0891932258279573 0.1736863105515 -0.0133146082606969"
        rpy="0 0 0" />
      <mass
        value="1.67275410091362" />
      <inertia
        ixx="0.00883526656815791"
        ixy="0.00363950973911315"
        ixz="0.000173170626109102"
        iyy="0.00361703472487365"
        iyz="-0.000337215822027566"
        izz="0.0114695151758111" />
    </inertial>
    <visual>
      <origin
        xyz="0 0 0"
        rpy="0 0 0" />
      <geometry>
        <mesh
          filename="package://exoskeleton_description/meshes/Left_Calf_Link.STL" />
      </geometry>
      <material
        name="">
        <color
          rgba="0.898039215686275 0.917647058823529 0.929411764705882 1" />
      </material>
    </visual>
    <collision>
      <origin
        xyz="0 0 0"
        rpy="0 0 0" />
      <geometry>
        <mesh
          filename="package://exoskeleton_description/meshes/Left_Calf_Link.STL" />
      </geometry>
    </collision>
  </link>
  <joint
    name="Left_Calf_Joint"
    type="revolute">
    <origin
      xyz="0.23966 0.28189 0"
      rpy="0 0 0" />
    <parent
      link="Left_Thigh_Link" />
    <child
      link="Left_Calf_Link" />
    <axis
      xyz="0 0 1" />
    <limit
      lower="-3.0543261"
      upper="3.0543261"
      effort="100"
      velocity="100" />
  </joint>
  <link
    name="Left_Ankle_Link">
    <inertial>
      <origin
        xyz="0.0464300413622986 0.0767918043386187 -0.0192031324458123"
        rpy="0 0 0" />
      <mass
        value="1.19036450922831" />
      <inertia
        ixx="0.00153091818368035"
        ixy="-6.61160505400838E-06"
        ixz="6.995899556434E-05"
        iyy="0.0064801204508979"
        iyz="-7.19796708189506E-06"
        izz="0.00598779799807743" />
    </inertial>
    <visual>
      <origin
        xyz="0 0 0"
        rpy="0 0 0" />
      <geometry>
        <mesh
          filename="package://exoskeleton_description/meshes/Left_Ankle_Link.STL" />
      </geometry>
      <material
        name="">
        <color
          rgba="0.898039215686275 0.917647058823529 0.929411764705882 1" />
      </material>
    </visual>
    <collision>
      <origin
        xyz="0 0 0"
        rpy="0 0 0" />
      <geometry>
        <mesh
          filename="package://exoskeleton_description/meshes/Left_Ankle_Link.STL" />
      </geometry>
    </collision>
  </link>
  <joint
    name="Left_Ankle_Joint"
    type="revolute">
    <origin
      xyz="-0.15989 0.31135 -0.025"
      rpy="0 0 0" />
    <parent
      link="Left_Calf_Link" />
    <child
      link="Left_Ankle_Link" />
    <axis
      xyz="0 0 1" />
    <limit
      lower="-3.0543261"
      upper="3.0543261"
      effort="100"
      velocity="100" />
  </joint>
  <link
    name="Right_Hip_Link">
    <inertial>
      <origin
        xyz="-1.46143295239251E-05 -0.0179780944726418 -0.0879462944917951"
        rpy="0 0 0" />
      <mass
        value="0.62649762055318" />
      <inertia
        ixx="0.000799976542001865"
        ixy="7.12950125025003E-08"
        ixz="2.30564615550973E-07"
        iyy="0.00122426246525867"
        iyz="2.94864770722133E-05"
        izz="0.000525653399653843" />
    </inertial>
    <visual>
      <origin
        xyz="0 0 0"
        rpy="0 0 0" />
      <geometry>
        <mesh
          filename="package://exoskeleton_description/meshes/Right_Hip_Link.STL" />
      </geometry>
      <material
        name="">
        <color
          rgba="0.792156862745098 0.819607843137255 0.933333333333333 1" />
      </material>
    </visual>
    <collision>
      <origin
        xyz="0 0 0"
        rpy="0 0 0" />
      <geometry>
        <mesh
          filename="package://exoskeleton_description/meshes/Right_Hip_Link.STL" />
      </geometry>
    </collision>
  </link>
  <joint
    name="Right_Hip_Joint"
    type="revolute">
    <origin
      xyz="0.2243 -0.208 -0.283"
      rpy="0 0 0" />
    <parent
      link="Back_Base_Link" />
    <child
      link="Right_Hip_Link" />
    <axis
      xyz="0 0 1" />
    <limit
      lower="-3.0543261"
      upper="3.0543261"
      effort="100"
      velocity="100" />
  </joint>
  <link
    name="Right_Thigh_Link">
    <inertial>
      <origin
        xyz="0.140021583192793 0.164739113884301 0.00687858578546396"
        rpy="0 0 0" />
      <mass
        value="1.98804772687662" />
      <inertia
        ixx="0.00824949609755381"
        ixy="-0.004128598728523"
        ixz="0.000302371461998384"
        iyy="0.00689306428252977"
        iyz="0.000354637810506685"
        izz="0.0133531919068961" />
    </inertial>
    <visual>
      <origin
        xyz="0 0 0"
        rpy="0 0 0" />
      <geometry>
        <mesh
          filename="package://exoskeleton_description/meshes/Right_Thigh_Link.STL" />
      </geometry>
      <material
        name="">
        <color
          rgba="0.898039215686275 0.917647058823529 0.929411764705882 1" />
      </material>
    </visual>
    <collision>
      <origin
        xyz="0 0 0"
        rpy="0 0 0" />
      <geometry>
        <mesh
          filename="package://exoskeleton_description/meshes/Right_Thigh_Link.STL" />
      </geometry>
    </collision>
  </link>
  <joint
    name="Right_Thigh_Joint"
    type="revolute">
    <origin
      xyz="0 0.012 -0.097"
      rpy="-1.5708 0 0" />
    <parent
      link="Right_Hip_Link" />
    <child
      link="Right_Thigh_Link" />
    <axis
      xyz="0 0 1" />
    <limit
      lower="-3.0543261"
      upper="3.0543261"
      effort="100"
      velocity="100" />
  </joint>
  <link
    name="Right_Calf_Link">
    <inertial>
      <origin
        xyz="-0.0891932258618637 0.173686310533376 0.013314608260754"
        rpy="0 0 0" />
      <mass
        value="1.67275410090321" />
      <inertia
        ixx="0.00883526656624898"
        ixy="0.00363950974045949"
        ixz="-0.000173170625517377"
        iyy="0.00361703472671801"
        iyz="0.000337215822330695"
        izz="0.0114695151757452" />
    </inertial>
    <visual>
      <origin
        xyz="0 0 0"
        rpy="0 0 0" />
      <geometry>
        <mesh
          filename="package://exoskeleton_description/meshes/Right_Calf_Link.STL" />
      </geometry>
      <material
        name="">
        <color
          rgba="0.898039215686275 0.917647058823529 0.929411764705882 1" />
      </material>
    </visual>
    <collision>
      <origin
        xyz="0 0 0"
        rpy="0 0 0" />
      <geometry>
        <mesh
          filename="package://exoskeleton_description/meshes/Right_Calf_Link.STL" />
      </geometry>
    </collision>
  </link>
  <joint
    name="Right_Calf_Joint"
    type="revolute">
    <origin
      xyz="0.23966 0.28189 0"
      rpy="0 0 0" />
    <parent
      link="Right_Thigh_Link" />
    <child
      link="Right_Calf_Link" />
    <axis
      xyz="0 0 1" />
    <limit
      lower="-3.0543261"
      upper="3.0543261"
      effort="100"
      velocity="100" />
  </joint>
  <link
    name="Right_Ankle_Link">
    <inertial>
      <origin
        xyz="0.0464300413623036 0.0767918043386194 0.0192030995150147"
        rpy="0 0 0" />
      <mass
        value="1.19036450922831" />
      <inertia
        ixx="0.00153091818368036"
        ixy="-6.61160505400814E-06"
        ixz="-6.99580154469131E-05"
        iyy="0.00648012045089792"
        iyz="7.19799618925579E-06"
        izz="0.00598779799807745" />
    </inertial>
    <visual>
      <origin
        xyz="0 0 0"
        rpy="0 0 0" />
      <geometry>
        <mesh
          filename="package://exoskeleton_description/meshes/Right_Ankle_Link.STL" />
      </geometry>
      <material
        name="">
        <color
          rgba="0.898039215686275 0.917647058823529 0.929411764705882 1" />
      </material>
    </visual>
    <collision>
      <origin
        xyz="0 0 0"
        rpy="0 0 0" />
      <geometry>
        <mesh
          filename="package://exoskeleton_description/meshes/Right_Ankle_Link.STL" />
      </geometry>
    </collision>
  </link>
  <joint
    name="Right_Ankle_Joint"
    type="revolute">
    <origin
      xyz="-0.15989 0.31135 0.025"
      rpy="0 0 0" />
    <parent
      link="Right_Calf_Link" />
    <child
      link="Right_Ankle_Link" />
    <axis
      xyz="0 0 1" />
    <limit
      lower="-3.0543261"
      upper="3.0543261"
      effort="100"
      velocity="100" />
  </joint>

  <!-- ROS base_link to UR 'Base' Coordinates transform -->
  <link  name = "base"/>
  <joint name = "base_link-base_fixed_joint" type="fixed">
    <!-- NOTE: this rotation is only needed as long as base_link itself is
               not corrected wrt the real robot (ie: rotated over 180
               degrees)
    -->
    <origin xyz="0 0 -1.1" rpy="0 0 0"/>
    <parent link="Back_Base_Link"/>
    <child link="base"/>
  </joint>

  <transmission name="Left_Hip_trans">
    <type>transmission_interface/SimpleTransmission</type>
    <joint name="Left_Hip_Joint">
      <hardwareInterface>PositionJointInterface</hardwareInterface>
    </joint>
    <actuator name="Left_Hip_motor">
      <mechanicalReduction>1</mechanicalReduction>
    </actuator>
  </transmission>

  <transmission name="Left_Thigh_trans">
    <type>transmission_interface/SimpleTransmission</type>
    <joint name="Left_Thigh_Joint">
      <hardwareInterface>PositionJointInterface</hardwareInterface>
    </joint>
    <actuator name="Left_Thigh_motor">
      <mechanicalReduction>1</mechanicalReduction>
    </actuator>
  </transmission>
  
  <transmission name="Left_Calf_trans">
    <type>transmission_interface/SimpleTransmission</type>
    <joint name="Left_Calf_Joint">
      <hardwareInterface>PositionJointInterface</hardwareInterface>
    </joint>
    <actuator name="Left_Calf_motor">
      <mechanicalReduction>1</mechanicalReduction>
    </actuator>
  </transmission>

  <transmission name="Left_Ankle_trans">
    <type>transmission_interface/SimpleTransmission</type>
    <joint name="Left_Ankle_Joint">
      <hardwareInterface>PositionJointInterface</hardwareInterface>
    </joint>
    <actuator name="Left_Ankle_motor">
      <mechanicalReduction>1</mechanicalReduction>
    </actuator>
  </transmission>

  <transmission name="Right_Hip_trans">
    <type>transmission_interface/SimpleTransmission</type>
    <joint name="Right_Hip_Joint">
      <hardwareInterface>PositionJointInterface</hardwareInterface>
    </joint>
    <actuator name="Right_Hip_motor">
      <mechanicalReduction>1</mechanicalReduction>
    </actuator>
  </transmission>

  <transmission name="Right_Thigh_trans">
    <type>transmission_interface/SimpleTransmission</type>
    <joint name="Right_Thigh_Joint">
      <hardwareInterface>PositionJointInterface</hardwareInterface>
    </joint>
    <actuator name="Right_Thigh_motor">
      <mechanicalReduction>1</mechanicalReduction>
    </actuator>
  </transmission>
  
  <transmission name="Right_Calf_trans">
    <type>transmission_interface/SimpleTransmission</type>
    <joint name="Right_Calf_Joint">
      <hardwareInterface>PositionJointInterface</hardwareInterface>
    </joint>
    <actuator name="Right_Calf_motor">
      <mechanicalReduction>1</mechanicalReduction>
    </actuator>
  </transmission>

  <transmission name="Right_Ankle_trans">
    <type>transmission_interface/SimpleTransmission</type>
    <joint name="Right_Ankle_Joint">
      <hardwareInterface>PositionJointInterface</hardwareInterface>
    </joint>
    <actuator name="Right_Ankle_motor">
      <mechanicalReduction>1</mechanicalReduction>
    </actuator>
  </transmission>

  <gazebo>
    <plugin name="gazebo_ros_control" filename="libgazebo_ros_control.so">
      <robotNamespace>/lower_limb</robotNamespace>
      <robotSimType>gazebo_ros_control/DefaultRobotHWSim</robotSimType>
      <legacyModeNS>true</legacyModeNS>
    </plugin>
  </gazebo>

</robot>
